Workbook

Sheet INPUTS
A1: REMEMBER FORWARD - LEXICON MODEL | yellow cells are inputs, everything else is formula
A2: Parameter | B2: Value | C2: Unit | D2: Note
A3: LEXICON STRUCTURE
A4: Tier 0 - semantic primes | B4: 65 | C4: words | D4: NSM primes (Wierzbicka). Fully pictogrammed, issued in every language.
A5: Tier 1 - core vocabulary | B5: 935 | C5: words | D5: To ~1000 total: Ogden Basic English 850 + Swadesh 207, merged and deduped.
A6: Tier 2 - long tail | B6: 4000 | C6: words | D6: To 5000 total. Defined strictly in Tier 1 vocabulary.
A7: Chars per headword block | B7: 22 | C7: chars | D7: Headword + part of speech + the paired second-language headword (Arabic).
A8: Chars per definition | B8: 108 | C8: chars | D8: ~18 words. Restricted-vocabulary definitions run long; a 12-word def would be ~72.
A9: Tier 0 pictogram coverage | B9: 1 | C9: fraction | D9: Every prime gets a pictogram.
A10: Tier 1 pictogram coverage | B10: 0.7 | C10: fraction | D10: Most of Basic English is picturable.
A11: Tier 2 pictogram coverage | B11: 0.25 | C11: fraction | D11: Abstract vocabulary resists depiction - this is the realistic ceiling.
A12: Pictogram size (square edge) | B12: 12 | C12: mm | D12: 12x12mm reads well unaided. Drives total area more than the text does.
A13: Layout overhead | B13: 0.4 | C13: fraction | D13: Margins, rules, gutters, card edges, index furniture, holes.
A14: DENSITY (anchored on Memory of Mankind published specs)
A15: Anchor type size | B15: 4 | C15: pt | D15: MOM individual-design spec: text at least 4pt Arial.
A16: Anchor density at that size | B16: 1.25 | C16: chars/mm2 | D16: MOM: 50,000 chars per 20x20cm tablet = 50000/40000.
A17: Microfilm density | B17: 125 | C17: chars/mm2 | D17: MOM ceramic microfilm: 5,000,000 chars per 20x20cm tablet. 5 lines/mm, needs 10x magnifier.
A18: UNAIDED tier type size | B18: 8 | C18: pt | D18: ~2mm cap height. Readable by aging eyes in poor light, no tools.
A19: FINE tier type size | B19: 4 | C19: pt | D19: Dictionary fine print. Young eye, or a cheap +3 reading lens.
A20: PANELS
A21: Titanium panel width | B21: 300 | C21: mm | D21: Typical PCM panel; 600x300 is a standard tray size.
A22: Titanium panel height | B22: 600 | C22: mm
A23: Titanium sides used | B23: 2 | C23: 1 or 2 | D23: PCM etches both sides in one pass - use 2.
A24: Ceramic tile width | B24: 300 | C24: mm | D24: NOT a ceramic limit. 20x20cm is MOM's ARCHIVE format. Large-format stoneware runs to 300x600.
A25: Ceramic tile height | B25: 600 | C25: mm | D25: Set 200/200 to model MOM archive tablets specifically.
A26: Ceramic sides used | B26: 2 | C26: 1 or 2 | D26: MOM print one face because they stack tablets. Edge-set on stilts and you can fire both.
A27: COST
A28: Titanium thickness | B28: 0.3 | C28: mm | D28: 0.2-0.5mm for cards. Thicker = stiffer but heavier deck.
A29: Titanium Grade 2 price | B29: 40 | C29: $/kg | D29: Range $30-50/kg for sheet.
A30: Titanium density | B30: 4.51 | C30: g/cm3 | D30: Grade 2. Fixed physical constant - do not edit.
A31: PCM etch cost per panel | B31: 28 | C31: $/panel | D31: Qty 100. Ti needs HF/nitric - fewer vendors, 1.5-2.5x stainless. Cost is per AREA, not per mark.
A32: PCM phototool per design | B32: 250 | C32: $/design | D32: One-time per unique panel artwork.
A33: CERAMIC - MAKE IN HOUSE (cost built up from components, not a placeholder)
A34: Tile thickness | B34: 6 | C34: mm | D34: 6mm resists warping at large format. Thicker = heavier, more clay, slower firing.
A35: Clay density (fired stoneware) | B35: 2.3 | C35: g/cm3 | D35: Physical constant - do not edit.
A36: Clay price | B36: 1 | C36: $/kg | D36: Stoneware body in quantity. Cheap; never the driver.
A37: Glaze per tile | B37: 0.3 | C37: $/tile | D37: Thin roller coat, MOM style.
A38: Kiln energy per firing | B38: 70 | C38: kWh | D38: ~7 cu ft kiln to cone 6.
A39: Electricity | B39: 0.2 | C39: $/kWh
A40: Tiles per firing | B40: 30 | C40: tiles | D40: Large-format tiles need shelf space; 20x20 tablets would fit far more.
...

Sheet DENSITY
A1: CHARACTER DENSITY vs TYPE SIZE (area scales as pt^2, calibrated to the MOM anchor)
A2: Mode | B2: Type size (pt) | C2: Cap height (mm) | D2: Chars / mm2 | E2: mm2 / char | F2: Reality check
A3: Large / Tier 0 display | B3: 12 | C3: =ROUND(B3*0.3528*0.7,2) | D3: =ROUND(INPUTS!$B$16*(INPUTS!$B$15/B3)^2,3) | E3: =ROUND(1/D3,3) | F3: Headline scale. Used for primes and card titles.
A4: Unaided (poor light, old eyes) | B4: =INPUTS!$B$18 | C4: =ROUND(B4*0.3528*0.7,2) | D4: =ROUND(INPUTS!$B$16*(INPUTS!$B$15/B4)^2,3) | E4: =ROUND(1/D4,3) | F4: The floor for 'no tools required'. ~2mm cap height.
A5: Compact unaided | B5: 6 | C5: =ROUND(B5*0.3528*0.7,2) | D5: =ROUND(INPUTS!$B$16*(INPUTS!$B$15/B5)^2,3) | E5: =ROUND(1/D5,3) | F5: Newspaper body text. Most adults, decent light.
A6: Fine / MOM standard | B6: =INPUTS!$B$19 | C6: =ROUND(B6*0.3528*0.7,2) | D6: =ROUND(INPUTS!$B$16*(INPUTS!$B$15/B6)^2,3) | E6: =ROUND(1/D6,3) | F6: MOM's own minimum for direct-read tablets. 50,000 chars per 20x20cm.
A7: Very fine (Ti PCM limit) | B7: 2 | C7: =ROUND(B7*0.3528*0.7,2) | D7: =ROUND(INPUTS!$B$16*(INPUTS!$B$15/B7)^2,3) | E7: =ROUND(1/D7,3) | F7: PCM min feature 0.1mm allows this. Needs a lens.
A8: CERAMIC MICROFILM | B8: ~0.5 | C8: 5 lines/mm | D8: =INPUTS!$B$17 | E8: =ROUND(1/D8,4) | F8: MOM ceramic microfilm. 5,000,000 chars per 20x20cm tablet. REQUIRES a 10x magnifier - hard dependency, see NOTES.
A10: Density gap between FINE and MICROFILM is ~100x. That gap is the whole ceramic argument.

Sheet LEXICON
A1: LEXICON CONTENT -> AREA REQUIRED
A2: Tier | B2: Words | C2: Chars/entry | D2: Total chars | E2: Text area @UNAIDED (mm2) | F2: Text area @FINE (mm2) | G2: Pictogram area (mm2) | H2: Pictograms
A3: Tier 0 - primes | B3: =INPUTS!$B$4 | C3: =INPUTS!$B$7+INPUTS!$B$8 | D3: =B3*C3 | E3: =D3*DENSITY!$E$4 | F3: =D3*DENSITY!$E$6 | G3: =H3*INPUTS!$B$12^2 | H3: =ROUND(B3*INPUTS!$B$9,0)
A4: Tier 1 - core | B4: =INPUTS!$B$5 | C4: =INPUTS!$B$7+INPUTS!$B$8 | D4: =B4*C4 | E4: =D4*DENSITY!$E$4 | F4: =D4*DENSITY!$E$6 | G4: =H4*INPUTS!$B$12^2 | H4: =ROUND(B4*INPUTS!$B$10,0)
A5: Tier 2 - long tail | B5: =INPUTS!$B$6 | C5: =INPUTS!$B$7+INPUTS!$B$8 | D5: =B5*C5 | E5: =D5*DENSITY!$E$4 | F5: =D5*DENSITY!$E$6 | G5: =H5*INPUTS!$B$12^2 | H5: =ROUND(B5*INPUTS!$B$11,0)
A6: TOTAL | B6: =SUM(B3:B5) | D6: =SUM(D3:D5) | E6: =SUM(E3:E5) | F6: =SUM(F3:F5) | G6: =SUM(G3:G5) | H6: =SUM(H3:H5)
A8: AREA ROLL-UP (includes overhead)
A9: Build | B9: Raw area mm2 | C9: With overhead mm2 | D9: m2
A10: UNAIDED everywhere | B10: =E6+G6 | C10: =B10*(1+INPUTS!$B$13) | D10: =ROUND(C10/1000000,3)
A11: FINE text + pictograms | B11: =F6+G6 | C11: =B11*(1+INPUTS!$B$13) | D11: =ROUND(C11/1000000,3)
A12: MICROFILM text only | B12: =D6*DENSITY!$E$8 | C12: =B12*(1+INPUTS!$B$13) | D12: =ROUND(C12/1000000,4)

Sheet MEDIA
A1: MEDIA COMPARISON - substrate cost and marking cost kept SEPARATE, because they scale differently
A3: KEY: substrate cost scales with AREA. Marking cost scales with AREA (etch/decal) or CHARACTER COUNT (laser). That difference, not the material, is what decides the price.
A5: Build | B5: Area (m2) | C5: Usable/sheet (mm2) | D5: Sheets | E5: Substrate $ | F5: Marking $ | G5: Tooling $ | H5: TOTAL $/set | I5: Note
A6: TITANIUM PCM - unaided 8pt | B6: =LEXICON!D10 | C6: =INPUTS!$B$21*INPUTS!$B$22*INPUTS!$B$23 | D6: =ROUNDUP(B6*1000000/C6,0) | E6: =ROUND(D6*(INPUTS!$B$21*INPUTS!$B$22*INPUTS!$B$28/1000*INPUTS!$B$30/1000*INPUTS!$B$29),2) | F6: =ROUND(D6*INPUTS!$B$31,2) | G6: =ROUND(D6*INPUTS!$B$32/INPUTS!$B$48,2) | H6: =ROUND(E6+F6+G6,2) | I6: No tools needed anywhere. Most robust, most panels.
A7: TITANIUM PCM - fine 4pt | B7: =LEXICON!D11 | C7: =INPUTS!$B$21*INPUTS!$B$22*INPUTS!$B$23 | D7: =ROUNDUP(B7*1000000/C7,0) | E7: =ROUND(D7*(INPUTS!$B$21*INPUTS!$B$22*INPUTS!$B$28/1000*INPUTS!$B$30/1000*INPUTS!$B$29),2) | F7: =ROUND(D7*INPUTS!$B$31,2) | G7: =ROUND(D7*INPUTS!$B$32/INPUTS!$B$48,2) | H7: =ROUND(E7+F7+G7,2) | I7: PCM min feature 0.1mm, so 4pt is easy. NO LASER AT ALL - the whole panel etches at once in a bath. This is why titanium is cheap: marking is per-area.
A8: CERAMIC + DECAL - fine 4pt | B8: =LEXICON!D11 | C8: =INPUTS!$B$24*INPUTS!$B$25*INPUTS!$B$26 | D8: =ROUNDUP(B8*1000000/C8,0) | E8: =ROUND(D8*((INPUTS!$B$24*INPUTS!$B$25*INPUTS!$B$34/1000*INPUTS!$B$35/1000*INPUTS!$B$36+INPUTS!$B$37)*(1+INPUTS!$B$42)+(INPUTS!$B$38*INPUTS!$B$39/INPUTS!$B$40*INPUTS!$B$41)),2) | F8: =ROUND(B8*INPUTS!$B$47,2) | G8: =ROUND(D8*INPUTS!$B$43/INPUTS!$B$48,2) | H8: =ROUND(E8+F8+G8,2) | I8: Screen / laser-toner ceramic decal, then fire. PER-AREA like PCM. 300dpi COLOUR, which titanium cannot do. This is the ceramic build for any real quantity.
A9: CERAMIC + LASER - fine 4pt | B9: =LEXICON!D11 | C9: =INPUTS!$B$24*INPUTS!$B$25*INPUTS!$B$26 | D9: =ROUNDUP(B9*1000000/C9,0) | E9: =ROUND(D9*((INPUTS!$B$24*INPUTS!$B$25*INPUTS!$B$34/1000*INPUTS!$B$35/1000*INPUTS!$B$36+INPUTS!$B$37)*(1+INPUTS!$B$42)+(INPUTS!$B$38*INPUTS!$B$39/INPUTS!$B$40*INPUTS!$B$41)),2) | F9: =ROUND((LEXICON!D6/INPUTS!$B$45/3600*INPUTS!$B$46),2) | G9: =ROUND(D9*INPUTS!$B$43/INPUTS!$B$48,2) | H9: =ROUND(E9+F9+G9,2) | I9: MOM's own method (engrave, then roller-glaze). Marking is PER-MARK: see MARKING TIME below. Fine for one-offs, brutal at qty 100.
A10: CERAMIC MICROFILM + LASER | B10: =LEXICON!D12 | C10: =INPUTS!$B$24*INPUTS!$B$25*INPUTS!$B$26 | D10: =ROUNDUP(B10*1000000/C10,0) | E10: =ROUND(D10*((INPUTS!$B$24*INPUTS!$B$25*INPUTS!$B$34/1000*INPUTS!$B$35/1000*INPUTS!$B$36+INPUTS!$B$37)*(1+INPUTS!$B$42)+(INPUTS!$B$38*INPUTS!$B$39/INPUTS!$B$40*INPUTS!$B$41)),2) | F10: =ROUND((LEXICON!D6/INPUTS!$B$45/3600*INPUTS!$B$46),2) | G10: =ROUND(D10*INPUTS!$B$43/INPUTS!$B$48,2) | H10: =ROUND(E10+F10+G10,2) | I10: Substrate cost collapses to almost nothing - but marking does NOT, because laser time tracks character count, not area. Microfilm saves material, never machine time.
A12: MARKING TIME (laser paths only) - the number that actually decides buy vs build
A13: Metric | B13: Value
A14: Characters in the lexicon | B14: =LEXICON!D6
A15: Laser hours per SET | B15: =ROUND(LEXICON!D6/INPUTS!$B$45/3600,2)
A16: Laser hours for the whole RUN | B16: =ROUND(LEXICON!D6/INPUTS!$B$45/3600*INPUTS!$B$48,0)
A17: Laser $ per set | B17: =ROUND((LEXICON!D6/INPUTS!$B$45/3600*INPUTS!$B$46),2)
A18: MOM absorb this only because Workshop of Photonics built them a purpose-made laser system, and because they make ONE-OFF tablets, not runs of 100.
A20: COST PER WORD
A21: Build | B21: $ / word
A22: Titanium PCM fine | B22: =ROUND(H7/LEXICON!B6,4)
A23: Ceramic + decal fine | B23: =ROUND(H8/LEXICON!B6,4)
A24: Ceramic + laser fine | B24: =ROUND(H9/LEXICON!B6,4)
A25: Ceramic microfilm + laser | B25: =ROUND(H10/LEXICON!B6,4)
A27: BUYING FROM MOM - an archival SERVICE, not a way to source tablets
A28: Product | B28: EUR | C28: USD | D28: What it actually buys
A29: MOM 1/4 tablet | B29: =INPUTS!$B$53 | C29: =ROUND(INPUTS!$B$53*INPUTS!$B$50,2) | D29: Cheapest entry. Slot in the Hallstatt salt mine + certificate + TOKEN.
A30: MOM 1/1 tablet | B30: =INPUTS!$B$51 | C30: =ROUND(INPUTS!$B$51*INPUTS!$B$50,2) | D30: Full tablet archived at Hallstatt + certificate + token.
A31: MOM 1/1 + duplicate | B31: =INPUTS!$B$52 | C31: =ROUND(INPUTS!$B$52*INPUTS!$B$50,2) | D31: THE ONE TO WANT: archived at Hallstatt AND a physical duplicate mailed back for your own capsule. Pointer runs both directions.
A32: You buy 1-2 of these as a COLLABORATION. You never buy 27 to source substrate - that would be paying MOM to archive 27 tablets in Austria, which is not the goal.
A33: RECOMMENDED BUILD - all three layers, deliberately
A34: Layer | B34: Medium | C34: Sheets | F34: Why
A35: Unaided core (Tier 0+1) | B35: Ceramic, colour | C35: =ROUNDUP((SUM(LEXICON!E3:E4)+SUM(LEXICON!G3:G4))*(1+INPUTS!$B$13)/(INPUTS!$B$24*INPUTS!$B$25*INPUTS!$B$26),0) | F35: 300dpi colour pictograms, no tools needed, MOM-proven in a salt mine. This layer is the expensive one - unaided legibility, not vocabulary size, is what costs area.
A36: Full lexicon, carried | B36: Titanium PCM 4pt | C36: =D7 | F36: Unbreakable, thin, snap-out cards, half-etch relief doubles as a printing plate.
A37: Full lexicon, archived | B37: Ceramic microfilm | C37: =D10 | F37: ~100x denser. Full redundancy at near-zero marginal area.
A38: Magnifier | B38: Glass / fused silica | C38: 1 | F38: Converts the microfilm dependency from a gamble into a supplied tool.
A39: MOM tokens | B39: Ceramic | C39: =INPUTS!$B$55 | F39: Points the finder at a second archive. Network topology, not an isolated deposit.

Sheet CARDS
A1: CARD FORMAT - how the lexicon divides into carryable cards
A2: Card format | B2: Area both sides (mm2) | C2: Entries per card | D2: Cards for whole lexicon | E2: Note
A3: ID-1 / membership card 85.6x54 | B3: =85.6*54*2 | C3: =ROUNDDOWN(B3/(LEXICON!C11/LEXICON!B6),0) | D3: =ROUNDUP(LEXICON!B6/C3,0) | E3: ISO 7810 ID-1. RECOMMENDED - the carrying unit is a topic, not a word.
A4: Key tag ~54x30 | B4: =54*30*2 | C4: =ROUNDDOWN(B4/(LEXICON!C11/LEXICON!B6),0) | D4: =ROUNDUP(LEXICON!B6/C4,0) | E4: Too few entries per card; 450+ cards is unsortable and loss-prone.
A5: Large card 105x74 (A7) | B5: =105*74*2 | C5: =ROUNDDOWN(B5/(LEXICON!C11/LEXICON!B6),0) | D5: =ROUNDUP(LEXICON!B6/C5,0) | E5: Fewer cards, less pocketable. Good for the Tier 0 pictogram set.
A6: One word per card | B6: =85.6*54*2 | C6: 1 | D6: =LEXICON!B6 | E6: 5000 loose objects, 30-40% of area lost to edges and holes. Rejected.
A8: DECK PHYSICALS (ID-1 in titanium)
A9: Mass per card (g) | B9: =ROUND(85.6*54*INPUTS!$B$28/1000*INPUTS!$B$30,2)
A10: Whole-deck mass (g) | B10: =ROUND(B9*D3,0)
A11: Whole-deck thickness (mm) | B11: =ROUND(INPUTS!$B$28*D3,0)
A12: Cards you actually carry (20%) | B12: =ROUNDUP(D3*0.2,0)
A14: You never carry the whole deck - that is the point of cards. Carry the Tier 0 set plus today's topic.

Sheet NOTES
A1: FINDINGS, CAVEATS, SOURCES
B2: CORRECTION - ceramic CAN carry the full 5000 words, and pictograms belong on both media
B3: The 0.30mm minimum-feature figure in plates/plate_profiles.py is a property of an assumed PROCESS
B4: (hand carving / underglaze brush / coarse decal), not of ceramic itself. MOM laser-engrave the tablet and
B5: then roller-apply glaze over it, so the mark sits in a recess under glass: no pigment bleed, no abrasion path.
B6: That is how they reach 5 lines/mm. ACTION: split the CERAMIC profile into CERAMIC_HAND (0.30mm) and
B7: CERAMIC_LASER (~0.05mm) in plate_profiles.py, and stop treating 0.30mm as a material constant.
B8: Ceramic also does 300dpi colour, which titanium cannot - anodising gives interference colour, not halftone.
B9: So ceramic should carry the RICHER pictograms and titanium the monochrome line versions. Both get pictograms.
B11: The real trade is the magnification dependency, not resolution
B12: Microfilm mode needs a 10x lens. For a project whose premise is 'no presumed viewer', that is a hard dependency.
B13: Three mitigations, use all of them: (1) ship a glass or fused-silica lens in the capsule - glass itself lasts
B14: millennia; (2) borrow the Long Now Rosetta Disk trick - a visible ramp of decreasing type that announces
... B22: Photonics built them a purpose-made laser system - their capital cost, not ours.
B23: => BUYING ceramic capacity from MOM may beat the $2,200-7,500 in-house kiln estimate until volume justifies it.
B25: NO STEEL - standing constraint as of 2026-09-01
B26: Kills the 316L card-stock option AND the enamel-on-steel fast-prototype route in the materials notes.
B27: Prototype substitute: anodised aluminium. Cheap, laser-markable, and a valve metal, so it is a true analogue
B28: for titanium anodising trials. Not archival - prototypes only. Anything that ships is titanium or ceramic.
B30: MOM collaboration - tokens in every capsule
B31: Two tokens per capsule is correct design: one extractable and carryable, one that stays with the capsule.
B32: Turns each deposit into a node pointing at another archive - network topology instead of isolated caches.
B33: Reciprocity: submit a Remember Forward tablet into the MOM archive so the pointer runs both directions.
B34: Tokens ship bundled with MOM tablet purchases, so buying ceramic capacity also sources tokens.
B35: Ask Kunze about bulk token supply and about a reciprocal deposit.
B36: CAVEAT: a pointer to Hallstatt only helps if Hallstatt survives and the finder can travel. Additive, never load-bearing.
B38: What is actually hard
... B59: 5. Which lens ships in the capsule, and does it need its own instruction plate?
